<?xml version='1.0'?>

<robot name="fouliex_bot" xmlns:xacro="http://www.ros.org/wiki/xacro">
    <xacro:include filename="$(find fouliex_bot)/urdf/fouliex_bot.gazebo"/>
    <link name="robot_footprint"></link>

    <joint name="robot_footprint_joint" type="fixed">
        <origin xyz="0 0 0" rpy="0 0 0"/>
        <parent link="robot_footprint"/>
        <child link="chassis"/>
    </joint>

    <!-- Chassis Link -->

    <link name='chassis'>
        <pose>0 0 0.1 0 0 0</pose>

        <inertial>
            <mass value="15.0"/>
            <origin xyz="0.0 0 0" rpy=" 0 0 0"/>
            <inertia ixx="0.1" ixy="0" ixz="0" iyy="0.1" iyz="0" izz="0.1"/>
        </inertial>

        <collision name='collision'>
            <origin xyz="0 0 0" rpy=" 0 0 0"/>
            <geometry>
                <box size=".4 .4 .1"/>
            </geometry>
        </collision>

        <visual name='chassis_visual'>
            <origin xyz="0 0 0" rpy=" 0 0 0"/>
            <geometry>
                <box size=".4 .4 .1"/>
            </geometry>
            <material name="black">
                <color rgba="0 0 0 1"/>
            </material>
        </visual>

        <collision name='back_caster_collision'>
            <origin xyz="-0.15 0 -0.05" rpy=" 0 0 0"/>
            <geometry>
                <sphere radius="0.05"/>
            </geometry>
            <surface>
                <friction>
                    <ode>
                        <mu>0</mu>
                        <mu2>0</mu2>
                        <slip1>1.0</slip1>
                        <slip2>1.0</slip2>
                    </ode>
                </friction>
            </surface>
        </collision>

        <visual name='back_caster_visual'>
            <origin xyz="-0.15 0 -0.05" rpy=" 0 0 0"/>
            <geometry>
                <sphere radius="0.05"/>
            </geometry>
        </visual>

        <collision name='front_caster_collision'>
            <origin xyz="0.15 0 -0.05" rpy=" 0 0 0"/>
            <geometry>
                <sphere radius="0.05"/>
            </geometry>
            <surface>
                <friction>
                    <ode>
                        <mu>0</mu>
                        <mu2>0</mu2>
                        <slip1>1.0</slip1>
                        <slip2>1.0</slip2>
                    </ode>
                </friction>
            </surface>
        </collision>

        <visual name='front_caster_visual'>
            <origin xyz="0.15 0 -0.05" rpy=" 0 0 0"/>
            <geometry>
                <sphere radius="0.05"/>
            </geometry>
        </visual>

    </link>

    <!-- Left Wheel Link -->

    <link name='left_wheel'>
        <inertial>
            <mass value="5.0"/>
            <origin xyz="0.0 0 0" rpy=" 0 1.5707 1.5707"/>
            <inertia ixx="0.1" ixy="0" ixz="0" iyy="0.1" iyz="0" izz="0.1"/>
        </inertial>

        <collision name='collision'>
            <origin xyz="0.0 0 0" rpy=" 0 1.5707 1.5707"/>
            <geometry>
                <cylinder length="0.05" radius="0.1"/>
            </geometry>
        </collision>

        <visual name='wheel_visual'>
            <origin xyz="0.0 0 0" rpy=" 0 1.5707 1.5707"/>
            <geometry>
                <cylinder length="0.05" radius="0.1"/>
            </geometry>
        </visual>
    </link>

    <!-- Right Wheel Link -->

    <link name='right_wheel'>
        <inertial>
            <mass value="5.0"/>
            <origin xyz="0.0 0 0" rpy=" 0 1.5707 1.5707"/>
            <inertia ixx="0.1" ixy="0" ixz="0" iyy="0.1" iyz="0" izz="0.1"/>
        </inertial>

        <collision name='collision'>
            <origin xyz="0.0 0 0" rpy=" 0 1.5707 1.5707"/>
            <geometry>
                <cylinder length="0.05" radius="0.1"/>
            </geometry>
        </collision>

        <visual name='wheel_visual'>
            <origin xyz="0.0 0 0" rpy=" 0 1.5707 1.5707"/>
            <geometry>
                <cylinder length="0.05" radius="0.1"/>
            </geometry>
        </visual>
    </link>

    <!-- Left and Right Wheel Joints -->
    <joint type="continuous" name="left_wheel_hinge">
        <origin xyz="0.0 0.25 0" rpy="0 0 0"/>
        <child link="left_wheel"/>
        <parent link="chassis"/>
        <axis xyz="0 1 0" rpy="0 0 0"/>
        <limit effort="10000" velocity="1000"/>
        <joint_properties damping="1.0" friction="1.0"/>
    </joint>

    <joint type="continuous" name="right_wheel_hinge">
        <origin xyz="0 -0.25 0" rpy="0 0 0"/>
        <child link="right_wheel"/>
        <parent link="chassis"/>
        <axis xyz="0 1 0" rpy="0 0 0"/>
        <limit effort="10000" velocity="1000"/>
        <joint_properties damping="1.0" friction="1.0"/>
    </joint>

    <!-- Camera Link -->

    <link name='camera'>
        <inertial>
            <mass value="0.1"/>
            <origin xyz="0.0 0 0" rpy=" 0 0 0"/>
            <inertia ixx="1e-6" ixy="0" ixz="0" iyy="1e-6" iyz="0" izz="1e-6"/>
        </inertial>

        <collision name='collision'>
            <origin xyz="0.0 0 0" rpy=" 0 0 0"/>
            <geometry>
                <box size="0.05 0.05 0.05"/>
            </geometry>
        </collision>

        <visual name='camera_visual'>
            <origin xyz="0.0 0 0" rpy=" 0 0 0"/>
            <geometry>
                <box size="0.05 0.05 0.05"/>
            </geometry>
        </visual>
    </link>

    <!-- Camera Joint -->
    <joint type="fixed" name="camera_joint">
        <origin xyz="0.2 0 0" rpy="0 0 0"/>
        <child link="camera"/>
        <parent link="chassis"/>
    </joint>

    <!-- Laser RangeFinder(hokuyo) Link -->

    <link name="hokuyo">

        <inertial>
            <mass value="0.1"/>
            <origin xyz="0 0 0" rpy="0 0 0"/>
            <inertia
                    ixx="1e-6" ixy="0" ixz="0"
                    iyy="1e-6" iyz="0"
                    izz="1e-6"
            />
        </inertial>
        <visual>
            <geometry>
                <mesh filename="package://fouliex_bot/meshes/hokuyo.dae"/>
            </geometry>
            <origin xyz="0 0 0" rpy="0 0 0"/>
        </visual>
        <collision>
            <geometry>
                <box size="0.1 0.1 0.1"/>
            </geometry>
            <origin xyz="0 0 0" rpy="0 0 0"/>
        </collision>
    </link>

    <!-- Laser RangeFinder(hokuyo) Link -->
    <joint type="fixed" name="hokuyo_joint">
        <origin xyz="0.15 0 0.1" rpy="0 0 0"/>
        <child link="hokuyo"/>
        <parent link="chassis"/>
    </joint>

</robot>
